File: data_processing/figures/2024_INL_Paper/fig_bending_tests/data/3PBT_R4N139 - 038_2024-01-16_1.csv
#Procedure: <__main__.FlexuralStressProcedure>
#Parameters:
#	Calibrated thickness: 9.5 mm
#	Deflection pot port: COM5
#	Experiment time: 30 s
#	Force gauge port: COM7
#	Run calibration: False
#	Sample diameter: 10.15 mm
#	Sample name: R4N139 - 038
#	Support span: 30 mm
#Data:
Time (s),Force (N),Flexural stress (Pa),Displacement (mm),Displacement err (mm)
0.0,0.0,0.0,-3.6,2.9000000000000004
0.037,0.0,0.0,-3.6,2.9000000000000004
0.068,0.0,0.0,-3.6,2.9000000000000004
0.308,0.0,0.0,-3.6,2.9000000000000004
0.129,0.0,0.0,-3.6,2.9000000000000004
0.156,0.0,0.0,-3.6,2.9000000000000004
0.189,0.0,0.0,-3.6,2.9000000000000004
0.22,0.0,0.0,-3.6,2.9000000000000004
0.251,0.0,0.0,-3.6,2.9000000000000004
0.281,0.0,0.0,-3.6,2.9000000000000004
0.338,0.0,0.0,-3.6,2.9000000000000004
0.364,0.0,0.0,-3.6,2.9000000000000004
0.39,0.0,0.0,-3.6,2.9000000000000004
0.41500000000000004,0.0,0.0,-3.6,2.9000000000000004
0.44,0.0,0.0,-3.6,2.9000000000000004
0.465,0.0,0.0,-3.6,2.9000000000000004
0.491,0.0,0.0,-3.6,2.9000000000000004
0.516,0.0,0.0,-3.6,2.9000000000000004
0.541,0.0,0.0,-3.6,2.9000000000000004
0.5670000000000001,0.0,0.0,-3.6,2.9000000000000004
0.593,0.0,0.0,-3.6,2.9000000000000004
0.619,0.0,0.0,-3.6,2.9000000000000004
0.644,0.0,0.0,-3.6,2.9000000000000004
0.67,0.0,0.0,-3.6,2.9000000000000004
0.6950000000000001,0.0,0.0,-3.6,2.9000000000000004
0.721,0.0,0.0,-3.6,2.9000000000000004
0.747,0.0,0.0,-3.6,2.9000000000000004
0.773,0.0,0.0,-3.6,2.9000000000000004
0.798,0.0,0.0,-3.6,2.9000000000000004
0.8230000000000001,0.0,0.0,-3.6,2.9000000000000004
0.848,0.0,0.0,-3.6,2.9000000000000004
0.873,0.0,0.0,-3.6,2.9000000000000004
0.899,0.0,0.0,-3.6,2.9000000000000004
0.925,0.0,0.0,-3.6,2.9000000000000004
0.9510000000000001,0.0,0.0,-3.6,2.9000000000000004
0.976,0.0,0.0,-3.6,2.9000000000000004
1.0010000000000001,0.0,0.0,-3.6,2.9000000000000004
1.026,0.0,0.0,-3.6,2.9000000000000004
1.052,0.0,0.0,-3.6,2.9000000000000004
1.078,0.0,0.0,-3.6,2.9000000000000004
1.103,0.0,0.0,-3.6,2.9000000000000004
1.129,0.0,0.0,-3.6,2.9000000000000004
1.156,0.0,0.0,-3.6,2.9000000000000004
1.181,0.0,0.0,-3.6,2.9000000000000004
1.207,0.0,0.0,-3.6,2.9000000000000004
1.232,0.0,0.0,-3.6,2.9000000000000004
1.2570000000000001,0.0,0.0,-3.6,2.9000000000000004
1.283,0.0,0.0,-3.6,2.9000000000000004
1.309,0.0,0.0,-3.6,2.9000000000000004
1.335,0.0,0.0,-3.6,2.9000000000000004
1.361,0.0,0.0,-3.6,2.9000000000000004
1.387,0.0,0.0,-3.6,2.9000000000000004
1.412,0.0,0.0,-3.6,2.9000000000000004
1.437,0.0,0.0,-3.6,2.9000000000000004
1.462,0.0,0.0,-3.6,2.9000000000000004
1.488,0.0,0.0,-3.6,2.9000000000000004
1.514,0.0,0.0,-3.6,2.9000000000000004
1.539,0.0,0.0,-3.6,2.9000000000000004
1.565,0.0,0.0,-3.6,2.9000000000000004
1.59,0.0,0.0,-3.6,2.9000000000000004
1.616,0.0,0.0,-3.6,2.9000000000000004
1.641,0.0,0.0,-3.6,2.9000000000000004
1.666,0.0,0.0,-3.6,2.9000000000000004
1.692,0.0,0.0,-3.6,2.9000000000000004
1.718,0.0,0.0,-3.6,2.9000000000000004
1.744,0.0,0.0,-3.6,2.9000000000000004
1.77,0.0,0.0,-3.6,2.9000000000000004
1.795,0.0,0.0,-3.6,2.9000000000000004
1.821,0.0,0.0,-3.6,2.9000000000000004
1.847,0.0,0.0,-3.6,2.9000000000000004
1.872,0.0,0.0,-3.6,2.9000000000000004
1.897,0.0,0.0,-3.6,2.9000000000000004
1.922,0.0,0.0,-3.6,2.9000000000000004
1.947,0.0,0.0,-3.6,2.9000000000000004
1.973,0.0,0.0,-3.6,2.9000000000000004
1.999,0.0,0.0,-3.6,2.9000000000000004
2.024,0.0,0.0,-3.6,2.9000000000000004
2.05,0.0,0.0,-3.6,2.9000000000000004
2.076,0.0,0.0,-3.6,2.9000000000000004
2.101,0.0,0.0,-3.6,2.9000000000000004
2.1270000000000002,0.0,0.0,-3.6,2.9000000000000004
2.152,0.0,0.0,-3.6,2.9000000000000004
2.177,0.0,0.0,-3.6,2.9000000000000004
2.202,0.0,0.0,-3.6,2.9000000000000004
2.228,0.0,0.0,-3.6,2.9000000000000004
2.254,0.0,0.0,-3.6,2.9000000000000004
2.279,0.0,0.0,-3.6,2.9000000000000004
2.305,0.0,0.0,-3.6,2.9000000000000004
2.33,0.0,0.0,-3.6,2.9000000000000004
2.356,0.0,0.0,-3.6,2.9000000000000004
2.3810000000000002,0.0,0.0,-3.6,2.9000000000000004
2.406,0.0,0.0,-3.6,2.9000000000000004
2.432,0.0,0.0,-3.6,2.9000000000000004
2.457,0.0,0.0,-3.6,2.9000000000000004
2.483,0.0,0.0,-3.6,2.9000000000000004
2.508,0.0,0.0,-3.6,2.9000000000000004
2.533,0.0,0.0,-3.6,2.9000000000000004
2.736,0.0,0.0,-3.6,2.9000000000000004
00000000004
2.583,0.0,0.0,-3.6,2.9000000000000004
2.609,0.0,0.0,-3.6,2.9000000000000004
2.634,0.0,0.0,-3.6,2.9000000000000004
2.6590000000000003,0.0,0.0,-3.6,2.9000000000000004
2.685,0.0,0.0,-3.6,2.9000000000000004
2.71,0.0,0.0,-3.6,2.9000000000000004
2.762,0.0,0.0,-3.6,2.9000000000000004
2.787,0.0,0.0,-3.6,2.9000000000000004
2.813,0.0,0.0,-3.6,2.9000000000000004
2.839,0.0,0.0,-3.6,2.9000000000000004
2.865,0.0,0.0,-3.6,2.9000000000000004
2.891,0.0,0.0,-3.6,2.9000000000000004
2.9170000000000003,0.0,0.0,-3.6,2.9000000000000004
2.942,0.0,0.0,-3.6,2.9000000000000004
2.967,0.0,0.0,-3.6,2.9000000000000004
2.993,0.0,0.0,-3.6,2.9000000000000004
3.0180000000000002,0.0,0.0,-3.6,2.9000000000000004
3.044,0.0,0.0,-3.6,2.9000000000000004
3.069,0.0,0.0,-3.6,2.9000000000000004
3.095,0.0,0.0,-3.6,2.9000000000000004
3.12,0.0,0.0,-3.6,2.9000000000000004
3.146,0.0,0.0,-3.6,2.9000000000000004
3.1710000000000003,0.0,0.0,-3.6,2.9000000000000004
3.196,0.0,0.0,-3.6,2.9000000000000004
3.222,0.0,0.0,-3.6,2.9000000000000004
3.247,0.0,0.0,-3.6,2.9000000000000004
3.273,0.0,0.0,-3.6,2.9000000000000004
3.298,0.0,0.0,-3.6,2.9000000000000004
3.323,0.0,0.0,-3.6,2.9000000000000004
3.349,0.0,0.0,-3.6,2.9000000000000004
3.374,0.0,0.0,-3.6,2.9000000000000004
3.399,0.0,0.0,-3.6,2.9000000000000004
3.424,0.0,0.0,-3.6,2.9000000000000004
3.4490000000000003,0.0,0.0,-3.6,2.9000000000000004
3.475,0.0,0.0,-3.6,2.9000000000000004
3.501,0.0,0.0,-3.6,2.9000000000000004
3.5260000000000002,0.0,0.0,-3.6,2.9000000000000004
3.551,0.0,0.0,-3.6,2.9000000000000004
3.577,0.0,0.0,-3.6,2.9000000000000004
3.602,0.0,0.0,-3.6,2.9000000000000004
3.628,0.0,0.0,-3.6,2.9000000000000004
3.653,0.0,0.0,-3.6,2.9000000000000004
3.678,0.0,0.0,-3.6,2.9000000000000004
3.7030000000000003,0.0,0.0,-3.6,2.9000000000000004
3.729,0.0,0.0,-3.6,2.9000000000000004
3.755,0.0,0.0,-3.6,2.9000000000000004
3.7800000000000002,0.0,0.0,-3.6,2.9000000000000004
3.806,0.0,0.0,-3.6,2.9000000000000004
3.831,0.0,0.0,-3.6,2.9000000000000004
3.856,0.0,0.0,-3.6,2.9000000000000004
3.882,0.0,0.0,-3.6,2.9000000000000004
3.907,0.0,0.0,-3.6,2.9000000000000004
3.9330000000000003,0.0,0.0,-3.6,2.9000000000000004
3.959,0.0,0.0,-3.6,2.9000000000000004
3.985,0.0,0.0,-3.6,2.9000000000000004
4.01,0.0,0.0,-3.6,2.9000000000000004
4.035,0.0,0.0,-3.6,2.9000000000000004
4.061,0.0,0.0,-3.6,2.9000000000000004
4.086,0.0,0.0,-3.6,2.9000000000000004
4.112,0.0,0.0,-3.6,2.9000000000000004
4.138,0.0,0.0,-3.6,2.9000000000000004
4.163,0.0,0.0,-3.6,2.9000000000000004
4.188,0.0,0.0,-3.6,2.9000000000000004
4.214,0.0,0.0,-3.6,2.9000000000000004
4.239,0.0,0.0,-3.6,2.9000000000000004
4.265,0.0,0.0,-3.6,2.9000000000000004
4.29,0.0,0.0,-3.6,2.9000000000000004
4.315,0.0,0.0,-3.6,2.9000000000000004
4.34,0.0,0.0,-3.6,2.9000000000000004
4.365,0.0,0.0,-3.6,2.9000000000000004
4.391,0.0,0.0,-3.6,2.9000000000000004
4.417,0.0,0.0,-3.6,2.9000000000000004
4.442,0.0,0.0,-3.6,2.9000000000000004
4.468,0.0,0.0,-3.6,2.9000000000000004
4.493,0.0,0.0,-3.6,2.9000000000000004
4.518,0.0,0.0,-3.6,2.9000000000000004
4.5440000000000005,0.0,0.0,-3.6,2.9000000000000004
4.57,0.0,0.0,-3.6,2.9000000000000004
4.595,0.0,0.0,-3.6,2.9000000000000004
4.62,0.0,0.0,-3.6,2.9000000000000004
4.646,0.0,0.0,-3.6,2.9000000000000004
4.671,0.0,0.0,-3.6,2.9000000000000004
4.696,0.0,0.0,-3.6,2.9000000000000004
4.722,0.0,0.0,-3.6,2.9000000000000004
4.748,0.0,0.0,-3.6,2.9000000000000004
4.774,0.0,0.0,-3.6,2.9000000000000004
4.799,0.0,0.0,-3.6,2.9000000000000004
4.825,0.0,0.0,-3.6,2.9000000000000004
4.8500000000000005,0.0,0.0,-3.6,2.9000000000000004
4.875,0.0,0.0,-3.6,2.9000000000000004
4.901,0.0,0.0,-3.6,2.9000000000000004
4.926,0.0,0.0,-3.6,2.9000000000000004
4.952,0.0,0.0,-3.6,2.9000000000000004
4.977,0.0,0.0,-3.6,2.9000000000000004
5.002,0.0,0.0,-3.6,2.9000000000000004
5.027,0.0,0.0,-3.6,2.9000000000000004
5.053,0.0,0.0,-3.6,2.9000000000000004
5.079,0.0,0.0,-3.5,2.9000000000000004
5.104,0.0,0.0,-3.5,2.8000000000000003
5.13,0.0,0.0,-3.4000000000000004,2.8000000000000003
5.155,0.0,0.0,-3.4000000000000004,2.8000000000000003
5.18,0.0,0.0,-3.4000000000000004,2.8000000000000003
5.206,0.0,0.0,-3.4000000000000004,2.8000000000000003
5.231,0.0,0.0,-3.4000000000000004,2.8000000000000003
5.257,0.0,0.0,-3.4000000000000004,2.8000000000000003
5.283,0.0,0.0,-3.4000000000000004,2.8000000000000003
5.308,0.0,0.0,-3.4000000000000004,2.8000000000000003
5.333,0.0,0.0,-3.3000000000000003,2.8000000000000003
5.359,0.0,0.0,-3.3000000000000003,2.7
5.385,0.0,0.0,-3.3000000000000003,2.7
5.41,0.0,0.0,-3.2,2.7
5.436,0.0,0.0,-3.2,2.7
5.461,0.0,0.0,-3.2,2.6
5.486,0.0,0.0,-3.2,2.6
5.5120000000000005,0.0,0.0,-3.1,2.6
5.538,0.0,0.0,-3.1,2.6
5.564,0.0,0.0,-3.1,2.6
5.589,0.0,0.0,-3.1,2.6
5.614,0.0,0.0,-3.1,2.6
5.64,0.0,0.0,-3.0,2.6
5.666,0.0,0.0,-3.0,2.5
5.691,0.0,0.0,-3.0,2.5
5.7170000000000005,0.0,0.0,-2.9000000000000004,2.5
5.743,0.0,0.0,-2.9000000000000004,2.5
5.769,0.0,0.0,-2.9000000000000004,2.5
5.7940000000000005,0.0,0.0,-2.9000000000000004,2.5
5.82,0.0,0.0,-2.8000000000000003,2.4000000000000004
5.846,0.0,0.0,-2.8000000000000003,2.4000000000000004
5.871,0.0,0.0,-2.8000000000000003,2.4000000000000004
5.897,0.0,0.0,-2.8000000000000003,2.4000000000000004
5.922,0.0,0.0,-2.7,2.4000000000000004
5.947,0.0,0.0,-2.7,2.4000000000000004
5.972,0.0,0.0,-2.7,2.3000000000000003
5.998,0.0,0.0,-2.6,2.3000000000000003
6.024,0.0,0.0,-2.6,2.3000000000000003
6.049,0.0,0.0,-2.6,2.3000000000000003
6.074,0.0,0.0,-2.5,2.3000000000000003
6.1000000000000005,0.0,0.0,-2.5,2.2
6.126,0.0,0.0,-2.5,2.2
6.151,0.0,0.0,-2.5,2.2
6.1770000000000005,0.0,0.0,-2.5,2.2
6.203,0.0,0.0,-2.5,2.2
6.228,0.0,0.0,-2.5,2.2
6.253,0.0,0.0,-2.5,2.2
6.2780000000000005,0.0,0.0,-2.5,2.2
6.303,0.0,0.0,-2.5,2.2
6.329,0.0,0.0,-2.5,2.2
6.354,0.0,0.0,-2.5,2.2
6.38,0.0,0.0,-2.5,2.2
6.405,0.0,0.0,-2.5,2.2
6.431,0.0,0.0,-2.4000000000000004,2.2
6.457,0.0,0.0,-2.4000000000000004,2.2
6.482,0.0,0.0,-2.4000000000000004,2.2
6.508,0.0,0.0,-2.4000000000000004,2.2
6.533,0.0,0.0,-2.3000000000000003,2.2
6.559,0.0,0.0,-2.3000000000000003,2.1
6.585,0.0,0.0,-2.3000000000000003,2.1
6.61,0.0,0.0,-2.3000000000000003,2.1
6.635,0.0,0.0,-2.3000000000000003,2.1
6.66,0.0,0.0,-2.3000000000000003,2.1
6.686,0.0,0.0,-2.3000000000000003,2.1
6.712,0.0,0.0,-2.3000000000000003,2.1
6.738,0.0,0.0,-2.2,2.1
6.763,0.0,0.0,-2.2,2.1
6.788,0.0,0.0,-2.2,2.1
6.814,0.0,0.0,-2.2,2.1
6.84,0.0,0.0,-2.2,2.1
6.865,0.0,0.0,-2.2,2.1
6.890000000000001,0.0,0.0,-2.1,2.1
6.916,0.0,0.0,-2.1,2.0
6.942,0.0,0.0,-2.1,2.0
6.968,0.0,0.0,-2.1,2.0
6.993,0.0,0.0,-2.1,2.0
7.018,0.0,0.0,-2.0,2.0
7.0440000000000005,0.0,0.0,-2.0,2.0
7.069,0.0,0.0,-2.0,2.0
7.095,0.0,0.0,-2.0,2.0
7.12,0.0,0.0,-1.9000000000000001,1.9000000000000001
7.146,0.0,0.0,-1.9000000000000001,1.9000000000000001
7.172,0.0,0.0,-1.9000000000000001,1.9000000000000001
7.197,0.0,0.0,-1.8,1.9000000000000001
7.223,0.0,0.0,-1.8,1.9000000000000001
7.2490000000000006,0.0,0.0,-1.8,1.9000000000000001
7.274,0.0,0.0,-1.8,1.9000000000000001
7.299,0.0,0.0,-1.8,1.9000000000000001
7.325,0.0,0.0,-1.7000000000000002,1.8
7.3500000000000005,0.0,0.0,-1.7000000000000002,1.8
7.376,0.0,0.0,-1.7000000000000002,1.8
7.401,0.0,0.0,-1.7000000000000002,1.8
7.4270000000000005,0.0,0.0,-1.6,1.8
7.452,0.0,0.0,-1.6,1.8
7.477,0.0,0.0,-1.6,1.8
7.502,0.0,0.0,-1.6,1.8
7.527,0.0,0.0,-1.6,1.8
7.553,0.0,0.0,-1.6,1.8
7.578,0.0,0.0,-1.5,1.7000000000000002
7.604,0.0,0.0,-1.5,1.7000000000000002
7.6290000000000004,0.0,0.0,-1.5,1.7000000000000002
7.654,0.0,0.0,-1.4000000000000001,1.7000000000000002
7.679,0.0,0.0,-1.4000000000000001,1.7000000000000002
7.705,0.0,0.0,-1.4000000000000001,1.7000000000000002
7.73,0.0,0.0,-1.4000000000000001,1.7000000000000002
7.756,0.0,0.0,-1.3,1.7000000000000002
7.781000000000001,0.0,0.0,-1.3,1.7000000000000002
7.807,0.0,0.0,-1.3,1.6
7.832,0.0,0.0,-1.3,1.6
7.8580000000000005,0.0,0.0,-1.2000000000000002,1.6
7.883,0.0,0.0,-1.2000000000000002,1.6
7.908,0.0,0.0,-1.2000000000000002,1.6
7.934,0.0,0.0,-1.1,1.6
7.9590000000000005,0.0,0.0,-1.1,1.6
7.984,0.0,0.0,-1.1,1.5
8.009,0.0,0.0,-1.1,1.5
8.035,0.0,0.0,-1.0,1.5
8.06,0.0,0.0,-1.0,1.5
8.086,0.0,0.0,-1.0,1.5
8.111,0.0,0.0,-0.9,1.5
8.136000000000001,0.0,0.0,-0.9,1.5
8.162,0.0,0.0,-0.9,1.5
8.188,0.0,0.0,-0.8,1.4000000000000001
8.214,0.0,0.0,-0.8,1.4000000000000001
8.239,0.0,0.0,-0.8,1.4000000000000001
8.264,0.0,0.0,-0.8,1.4000000000000001
8.290000000000001,0.0,0.0,-0.7000000000000001,1.4000000000000001
8.316,0.0,0.0,-0.7000000000000001,1.4000000000000001
8.341,0.0,0.0,-0.7000000000000001,1.4000000000000001
8.367,0.0,0.0,-0.7000000000000001,1.4000000000000001
8.392,0.0,0.0,-0.6000000000000001,1.4000000000000001
8.418000000000001,0.0,0.0,-0.6000000000000001,1.4000000000000001
8.444,0.0,0.0,-0.6000000000000001,1.4000000000000001
8.469,0.0,0.0,-0.6000000000000001,1.3
8.494,0.0,0.0,-0.6000000000000001,1.3
8.52,0.0,0.0,-0.5,1.3
8.545,0.0,0.0,-0.5,1.3
8.57,0.0,0.0,-0.5,1.3
8.595,0.0,0.0,-0.5,1.3
8.621,0.0,0.0,-0.5,1.3
8.646,0.0,0.0,-0.5,1.3
8.672,0.0,0.0,-0.4,1.3
8.697000000000001,0.0,0.0,-0.4,1.3
8.722,0.0,0.0,-0.4,1.3
8.747,0.0,0.0,-0.4,1.3
8.773,0.0,0.0,-0.4,1.3
8.798,0.0,0.0,-0.30000000000000004,1.3
8.824,0.0,0.0,-0.30000000000000004,1.3
8.85,0.0,0.0,-0.30000000000000004,1.3
8.875,0.0,0.0,-0.30000000000000004,1.2000000000000002
8.901,0.0,0.0,-0.30000000000000004,1.2000000000000002
8.926,0.0,0.0,-0.30000000000000004,1.2000000000000002
8.951,0.0,0.0,-0.2,1.2000000000000002
8.977,0.0,0.0,-0.2,1.2000000000000002
9.002,0.0,0.0,-0.2,1.2000000000000002
9.028,0.0,0.0,-0.2,1.2000000000000002
9.053,0.0,0.0,-0.1,1.2000000000000002
9.079,0.0,0.0,-0.1,1.2000000000000002
9.104000000000001,0.0,0.0,-0.1,1.2000000000000002
9.13,0.0,0.0,-0.1,1.2000000000000002
9.156,0.0,0.0,-0.1,1.2000000000000002
9.181000000000001,0.0,0.0,-0.1,1.2000000000000002
9.207,0.0,0.0,-0.1,1.2000000000000002
9.232,0.0,0.0,0.0,1.2000000000000002
9.258000000000001,0.0,0.0,0.0,1.2000000000000002
9.284,0.0,0.0,0.0,1.1
9.309000000000001,0.0,0.0,0.0,1.1
9.335,0.0,0.0,0.0,1.1
9.36,0.0,0.0,0.0,1.1
9.385,0.0,0.0,0.0,1.1
9.41,0.0,0.0,0.1,1.1
9.436,0.0,0.0,0.1,1.1
9.461,0.0,0.0,0.1,1.1
9.486,0.0,0.0,0.1,1.1
9.512,0.0,0.0,0.1,1.1
9.537,0.0,0.0,0.1,1.1
9.563,0.0,0.0,0.1,1.1
9.589,0.0,0.0,0.1,1.1
9.615,0.0,0.0,0.1,1.1
9.64,0.0,0.0,0.1,1.1
9.665000000000001,0.0,0.0,0.1,1.1
9.69,0.0,0.0,0.1,1.1
9.716000000000001,0.0,0.0,0.1,1.1
9.741,0.0,0.0,0.1,1.1
9.766,0.0,0.0,0.2,1.1
9.792,0.0,0.0,0.2,1.1
9.817,0.0,0.0,0.2,1.1
9.843,0.0,0.0,0.2,1.1
9.869,0.0,0.0,0.2,1.1
9.894,0.0,0.0,0.2,1.1
9.92,0.0,0.0,0.2,1.1
9.945,0.0,0.0,0.2,1.1
9.971,0.0,0.0,0.2,1.1
9.996,0.0,0.0,0.2,1.1
10.021,0.0,0.0,0.2,1.1
10.047,0.0,0.0,0.2,1.1
10.072000000000001,0.0,0.0,0.2,1.1
10.098,0.0,0.0,0.30000000000000004,1.1
10.123,0.0,0.0,0.30000000000000004,1.1
10.149000000000001,0.0,0.0,0.30000000000000004,1.1
10.175,0.0,0.0,0.30000000000000004,1.1
10.200000000000001,0.0,0.0,0.30000000000000004,1.1
10.225,0.0,0.0,0.30000000000000004,1.1
10.25,0.0,0.0,0.30000000000000004,1.1
10.276,0.0,0.0,0.30000000000000004,1.1
10.301,0.0,0.0,0.30000000000000004,1.1
10.327,0.0,0.0,0.30000000000000004,1.1
10.352,0.0,0.0,0.30000000000000004,1.1
10.378,0.0,0.0,0.30000000000000004,1.1
10.403,0.0,0.0,0.30000000000000004,1.0
10.429,0.0,0.0,0.4,1.0
10.454,0.0,0.0,0.4,1.0
10.48,0.0,0.0,0.4,1.0
10.505,0.0,0.0,0.4,1.0
10.53,0.0,0.0,0.4,1.0
10.556000000000001,0.0,0.0,0.4,1.0
10.581,0.0,0.0,0.4,1.0
10.607000000000001,0.0,0.0,0.4,1.0
10.633000000000001,0.0,0.0,0.4,1.0
10.658,0.0,0.0,0.4,1.0
10.684000000000001,0.0,0.0,0.4,1.0
10.709,0.0,0.0,0.4,1.0
10.735,0.0,0.0,0.4,1.0
10.761000000000001,0.0,0.0,0.4,1.0
10.787,0.0,0.0,0.4,1.0
10.812,0.0,0.0,0.4,1.0
10.837,0.0,0.0,0.4,1.0
10.863,0.0,0.0,0.4,1.0
10.888,0.0,0.0,0.4,1.0
10.914,0.0,0.0,0.4,1.0
10.939,0.0,0.0,0.4,1.0
10.964,0.0,0.0,0.4,1.0
10.99,0.0,0.0,0.4,1.0
11.016,0.0,0.0,0.4,1.0
11.041,0.0,0.0,0.4,1.0
11.067,0.0,0.0,0.4,1.0
11.093,0.0,0.0,0.4,1.0
11.118,0.0,0.0,0.4,1.0
11.143,0.0,0.0,0.4,1.0
11.168000000000001,0.0,0.0,0.4,1.0
11.193,0.0,0.0,0.4,1.0
11.218,0.0,0.0,0.4,1.0
11.244,0.0,0.0,0.5,1.0
11.269,0.0,0.0,0.5,1.0
11.295,0.0,0.0,0.5,1.0
11.321,0.0,0.0,0.5,1.0
11.346,0.0,0.0,0.5,1.0
11.371,0.0,0.0,0.5,1.0
11.397,0.0,0.0,0.5,1.0
11.422,0.0,0.0,0.5,1.0
11.448,0.0,0.0,0.5,1.0
11.473,0.0,0.0,0.5,1.0
11.499,0.0,0.0,0.5,1.0
11.524000000000001,0.0,0.0,0.5,1.0
11.549,0.0,0.0,0.5,1.0
11.575000000000001,0.0,0.0,0.5,1.0
11.6,0.0,0.0,0.5,1.0
11.626,0.0,0.0,0.5,1.0
11.651,0.0,0.0,0.5,1.0
11.677,0.0,0.0,0.5,1.0
11.702,0.0,0.0,0.5,1.0
11.728,0.0,0.0,0.5,1.0
11.753,0.0,0.0,0.5,1.0
11.779,0.0,0.0,0.5,1.0
11.805,0.0,0.0,0.5,1.0
11.83,0.0,0.0,0.5,1.0
11.856,0.0,0.0,0.5,1.0
11.881,0.0,0.0,0.5,1.0
11.907,0.0,0.0,0.5,1.0
11.932,0.0,0.0,0.5,1.0
11.958,0.0,0.0,0.6000000000000001,1.0
11.984,0.0,0.0,0.6000000000000001,1.0
12.009,0.0,0.0,0.6000000000000001,1.0
12.034,0.0,0.0,0.6000000000000001,1.0
12.059000000000001,0.0,0.0,0.6000000000000001,1.0
12.085,0.0,0.0,0.6000000000000001,1.0
12.112,0.0,0.0,0.6000000000000001,1.0
12.138,0.0,0.0,0.6000000000000001,1.0
12.163,0.0,0.0,0.6000000000000001,1.0
12.188,0.0,0.0,0.6000000000000001,1.0
12.214,0.0,0.0,0.6000000000000001,1.0
12.24,0.0,0.0,0.6000000000000001,1.0
12.265,0.0,0.0,0.6000000000000001,1.0
12.290000000000001,0.0,0.0,0.6000000000000001,1.0
12.315,0.0,0.0,0.6000000000000001,1.0
12.341000000000001,0.0,0.0,0.6000000000000001,1.0
12.366,0.0,0.0,0.6000000000000001,1.0
12.392,0.0,0.0,0.6000000000000001,1.0
12.418000000000001,0.0,0.0,0.6000000000000001,1.0
12.443,0.0,0.0,0.6000000000000001,1.0
12.468,0.0,0.0,0.6000000000000001,1.0
12.493,0.0,0.0,0.6000000000000001,1.0
12.519,0.0,0.0,0.6000000000000001,1.0
12.545,0.0,0.0,0.6000000000000001,1.0
12.57,0.0,0.0,0.6000000000000001,1.0
12.596,0.0,0.0,0.6000000000000001,1.0
12.621,0.0,0.0,0.6000000000000001,1.0
12.647,0.0,0.0,0.6000000000000001,1.0
12.672,0.0,0.0,0.6000000000000001,1.0
12.697000000000001,0.0,0.0,0.7000000000000001,1.0
12.877,0.0,0.0,0.7000000000000001,1.0
12.749,0.0,0.0,0.7000000000000001,1.0
12.774000000000001,0.0,0.0,0.7000000000000001,1.0
12.8,0.0,0.0,0.7000000000000001,1.0
12.825000000000001,0.0,0.0,0.7000000000000001,1.0
12.851,0.0,0.0,0.7000000000000001,1.0
13.106,0.0,0.0,0.7000000000000001,0.9
000001,1.0
12.927,0.0,0.0,0.7000000000000001,1.0
12.953,0.0,0.0,0.7000000000000001,1.0
12.979000000000001,0.0,0.0,0.7000000000000001,1.0
13.004,0.0,0.0,0.7000000000000001,1.0
13.029,0.0,0.0,0.7000000000000001,0.9
13.055,0.0,0.0,0.7000000000000001,0.9
13.081,0.0,0.0,0.7000000000000001,0.9
13.131,0.0,0.0,0.7000000000000001,0.9
13.157,0.0,0.0,0.7000000000000001,0.9
13.182,0.0,0.0,0.7000000000000001,0.9
13.207,0.0,0.0,0.7000000000000001,0.9
13.233,0.0,0.0,0.8,0.9
13.259,0.0,0.0,0.8,0.9
13.284,0.0,0.0,0.8,0.9
13.309000000000001,0.0,0.0,0.8,0.9
13.335,0.0,0.0,0.8,0.9
13.36,0.0,0.0,0.8,0.9
13.386000000000001,0.0,0.0,0.8,0.9
13.411,0.0,0.0,0.8,0.9
13.437000000000001,0.0,0.0,0.8,0.9
13.462,0.0,0.0,0.8,0.9
13.487,0.0,0.0,0.8,0.9
13.512,0.0,0.0,0.8,0.9
13.538,0.0,0.0,0.8,0.9
13.564,0.0,0.0,0.8,0.9
13.59,0.0,0.0,0.8,0.9
13.615,0.0,0.0,0.8,0.9
13.641,0.3,21917.171047199787,0.8,0.9
13.667,0.4,29222.89472959972,0.8,0.9
13.692,0.5,36528.618411999654,0.8,0.9
13.718,0.5,36528.618411999654,0.9,0.9
13.744,0.5,36528.618411999654,0.9,0.9
13.77,0.5,36528.618411999654,0.9,0.9
13.795,0.5,36528.618411999654,0.9,0.9
13.821,0.5,36528.618411999654,0.9,0.9
13.846,0.5,36528.618411999654,0.9,0.9
13.872,0.5,36528.618411999654,0.9,0.9
13.898,0.6,43834.34209439957,0.9,0.9
13.924,0.6,43834.34209439957,0.9,0.9
13.949,0.6,43834.34209439957,0.9,0.9
13.974,0.7000000000000001,51140.065776799514,0.9,0.9
13.999,0.8,58445.78945919944,0.9,0.9
14.025,0.9,65751.51314159937,0.9,0.9
14.05,1.0,73057.23682399931,0.9,0.9
14.076,1.1,80362.96050639922,0.9,0.9
14.101,1.1,80362.96050639922,0.9,0.9
14.128,1.2,87668.68418879915,0.9,0.9
14.153,1.2,87668.68418879915,0.9,0.9
14.178,1.2,87668.68418879915,0.9,0.9
14.204,1.2,87668.68418879915,0.9,0.9
14.23,1.3,94974.40787119909,0.9,0.9
14.255,1.3,94974.40787119909,0.9,0.9
14.280000000000001,1.3,94974.40787119909,0.9,0.9
14.306000000000001,1.3,94974.40787119909,0.9,0.9
14.331,1.3,94974.40787119909,0.9,0.9
14.357000000000001,1.2,87668.68418879915,0.9,0.9
14.382,1.2,87668.68418879915,0.9,0.9
14.407,1.3,94974.40787119909,0.9,0.9
14.433,1.3,94974.40787119909,0.9,0.9
14.458,1.4000000000000001,102280.13155359903,0.9,0.9
14.484,1.5,109585.85523599896,0.9,0.9
14.51,1.5,109585.85523599896,0.9,0.9
14.535,1.5,109585.85523599896,0.9,0.9
14.561,1.5,109585.85523599896,1.0,0.9
14.586,1.4000000000000001,102280.13155359903,1.0,0.9
14.611,1.2,87668.68418879915,1.0,0.9
14.637,1.1,80362.96050639922,1.0,0.9
14.663,1.0,73057.23682399931,1.0,0.9
14.688,1.0,73057.23682399931,1.0,0.9
14.714,0.8,58445.78945919944,1.0,0.9
14.739,0.8,58445.78945919944,1.0,0.9
14.765,0.7000000000000001,51140.065776799514,1.0,0.9
14.790000000000001,0.6,43834.34209439957,1.0,0.9
14.815,0.6,43834.34209439957,1.0,0.9
14.841000000000001,0.5,36528.618411999654,1.0,0.9
14.866,0.4,29222.89472959972,1.0,0.9
14.891,0.4,29222.89472959972,1.0,0.9
14.917,0.4,29222.89472959972,1.0,0.9
14.943,0.4,29222.89472959972,1.1,0.9
14.968,0.3,21917.171047199787,1.1,0.9
14.994,0.3,21917.171047199787,1.1,0.9
15.019,0.3,21917.171047199787,1.1,0.9
15.045,0.3,21917.171047199787,1.1,0.9
15.071,0.3,21917.171047199787,1.1,0.9
15.096,0.3,21917.171047199787,1.1,0.9
15.122,0.3,21917.171047199787,1.1,0.9
15.148,0.3,21917.171047199787,1.1,0.9
15.173,0.3,21917.171047199787,1.1,0.9
15.199,0.3,21917.171047199787,1.1,0.9
15.224,0.3,21917.171047199787,1.1,0.9
15.249,0.3,21917.171047199787,1.1,0.9
15.275,0.3,21917.171047199787,1.1,0.9
15.301,0.3,21917.171047199787,1.1,0.9
15.326,0.3,21917.171047199787,1.1,0.9
15.352,0.3,21917.171047199787,1.1,0.9
15.377,0.3,21917.171047199787,1.2000000000000002,0.9
15.402000000000001,0.3,21917.171047199787,1.2000000000000002,0.8
15.428,0.3,21917.171047199787,1.2000000000000002,0.8
15.453000000000001,0.3,21917.171047199787,1.2000000000000002,0.8
15.479000000000001,0.3,21917.171047199787,1.2000000000000002,0.8
15.504,0.3,21917.171047199787,1.2000000000000002,0.8
15.530000000000001,0.3,21917.171047199787,1.2000000000000002,0.8
15.556000000000001,0.3,21917.171047199787,1.2000000000000002,0.8
15.581,0.3,21917.171047199787,1.2000000000000002,0.8
15.606,0.2,14611.44736479986,1.2000000000000002,0.8
15.632,0.2,14611.44736479986,1.2000000000000002,0.8
15.657,0.2,14611.44736479986,1.2000000000000002,0.8
15.683,0.2,14611.44736479986,1.2000000000000002,0.8
15.709,0.2,14611.44736479986,1.2000000000000002,0.8
15.734,0.2,14611.44736479986,1.3,0.8
15.76,0.2,14611.44736479986,1.3,0.8
15.786,0.2,14611.44736479986,1.3,0.8
15.811,0.2,14611.44736479986,1.3,0.8
15.836,0.2,14611.44736479986,1.3,0.8
15.862,0.2,14611.44736479986,1.3,0.8
15.888,0.2,14611.44736479986,1.3,0.8
15.913,0.2,14611.44736479986,1.3,0.8
15.939,0.0,0.0,1.3,0.8
15.965,0.0,0.0,1.3,0.8
15.99,0.0,0.0,1.3,0.8
16.015,0.0,0.0,1.4000000000000001,0.8
16.04,0.0,0.0,1.4000000000000001,0.8
16.065,0.0,0.0,1.4000000000000001,0.8
16.091,0.0,0.0,1.4000000000000001,0.8
16.117,0.0,0.0,1.4000000000000001,0.8
16.143,0.0,0.0,1.4000000000000001,0.8
16.168,0.0,0.0,1.4000000000000001,0.8
16.194,0.0,0.0,1.4000000000000001,0.8
16.219,0.0,0.0,1.4000000000000001,0.8
16.245,0.0,0.0,1.4000000000000001,0.8
16.271,0.0,0.0,1.4000000000000001,0.8
16.297,0.0,0.0,1.4000000000000001,0.8
16.322,0.0,0.0,1.5,0.8
16.348,0.0,0.0,1.5,0.8
16.373,0.0,0.0,1.5,0.8
16.399,0.0,0.0,1.5,0.8
16.424,0.0,0.0,1.5,0.8
16.45,0.0,0.0,1.5,0.8
16.475,0.0,0.0,1.6,0.8
16.501,0.0,0.0,1.6,0.8
16.526,0.0,0.0,1.6,0.8
16.552,0.0,0.0,1.6,0.8
16.577,0.0,0.0,1.6,0.8
16.603,0.0,0.0,1.6,0.8
16.628,0.0,0.0,1.6,0.8
16.654,0.0,0.0,1.7000000000000002,0.8
16.679000000000002,0.0,0.0,1.7000000000000002,0.8
16.704,0.0,0.0,1.7000000000000002,0.8
16.73,0.0,0.0,1.7000000000000002,0.8
16.755,0.0,0.0,1.7000000000000002,0.8
16.781,0.0,0.0,1.8,0.7000000000000001
16.806,0.0,0.0,1.8,0.7000000000000001
16.831,0.0,0.0,1.8,0.7000000000000001
16.856,0.0,0.0,1.8,0.7000000000000001
16.882,0.0,0.0,1.8,0.7000000000000001
16.907,0.0,0.0,1.8,0.7000000000000001
16.933,0.0,0.0,1.9000000000000001,0.7000000000000001
16.959,0.0,0.0,1.9000000000000001,0.7000000000000001
16.984,0.0,0.0,1.9000000000000001,0.7000000000000001
17.009,0.0,0.0,1.9000000000000001,0.7000000000000001
17.035,0.0,0.0,1.9000000000000001,0.7000000000000001
17.061,0.0,0.0,1.9000000000000001,0.7000000000000001
17.086000000000002,0.0,0.0,1.9000000000000001,0.7000000000000001
17.112000000000002,0.0,0.0,1.9000000000000001,0.7000000000000001
17.138,0.0,0.0,1.9000000000000001,0.7000000000000001
17.163,0.0,0.0,1.9000000000000001,0.7000000000000001
17.189,0.0,0.0,1.9000000000000001,0.7000000000000001
17.215,0.0,0.0,1.9000000000000001,0.7000000000000001
17.241,0.0,0.0,1.9000000000000001,0.7000000000000001
17.266000000000002,0.0,0.0,1.9000000000000001,0.7000000000000001
17.292,0.0,0.0,1.9000000000000001,0.7000000000000001
17.317,0.0,0.0,1.9000000000000001,0.7000000000000001
17.342,0.0,0.0,1.9000000000000001,0.7000000000000001
17.367,0.0,0.0,1.9000000000000001,0.7000000000000001
17.393,0.0,0.0,1.9000000000000001,0.7000000000000001
17.418,0.0,0.0,1.9000000000000001,0.7000000000000001
17.444,0.0,0.0,1.9000000000000001,0.7000000000000001
17.469,0.0,0.0,1.9000000000000001,0.7000000000000001
17.494,0.0,0.0,1.9000000000000001,0.7000000000000001
17.52,0.0,0.0,1.9000000000000001,0.7000000000000001
17.546,0.0,0.0,1.9000000000000001,0.7000000000000001
17.571,0.0,0.0,1.8,0.7000000000000001
17.596,0.0,0.0,1.8,0.7000000000000001
17.622,0.0,0.0,1.7000000000000002,0.7000000000000001
17.648,0.0,0.0,1.7000000000000002,0.8
17.673000000000002,0.0,0.0,1.7000000000000002,0.8
17.699,0.0,0.0,1.6,0.8
17.724,0.0,0.0,1.6,0.8
17.75,0.0,0.0,1.6,0.8
17.775000000000002,0.0,0.0,1.6,0.8
17.801000000000002,0.0,0.0,1.6,0.8
17.827,0.0,0.0,1.6,0.8
17.853,0.0,0.0,1.5,0.8
17.878,0.0,0.0,1.5,0.8
17.903,0.0,0.0,1.5,0.8
17.929000000000002,0.0,0.0,1.4000000000000001,0.8
17.955000000000002,0.0,0.0,1.4000000000000001,0.8
17.98,0.0,0.0,1.4000000000000001,0.8
18.008,0.0,0.0,1.4000000000000001,0.8
18.033,0.0,0.0,1.4000000000000001,0.8
18.058,0.0,0.0,1.4000000000000001,0.8
18.084,0.0,0.0,1.4000000000000001,0.8
18.11,0.0,0.0,1.4000000000000001,0.8
18.135,0.0,0.0,1.4000000000000001,0.8
18.161,0.0,0.0,1.4000000000000001,0.8
18.186,0.0,0.0,1.4000000000000001,0.8
18.212,0.0,0.0,1.4000000000000001,0.8
18.237000000000002,0.0,0.0,1.4000000000000001,0.8
18.262,0.0,0.0,1.4000000000000001,0.8
18.288,0.0,0.0,1.4000000000000001,0.8
18.313,0.0,0.0,1.4000000000000001,0.8
18.339,0.0,0.0,1.4000000000000001,0.8
18.364,0.0,0.0,1.4000000000000001,0.8
18.39,0.0,0.0,1.4000000000000001,0.8
18.415,0.0,0.0,1.4000000000000001,0.8
18.441,0.0,0.0,1.4000000000000001,0.8
18.466,0.0,0.0,1.2000000000000002,0.8
18.492,0.0,0.0,1.0,0.9
18.517,0.0,0.0,0.8,0.9
18.543,0.0,0.0,0.6000000000000001,1.0
18.568,0.0,0.0,0.5,1.0
18.593,0.0,0.0,0.4,1.0
18.618000000000002,0.0,0.0,0.30000000000000004,1.1
18.643,0.0,0.0,0.2,1.1
18.669,0.0,0.0,0.1,1.1
18.694,0.0,0.0,0.0,1.1
18.72,0.0,0.0,-0.1,1.2000000000000002
18.746,0.0,0.0,-0.1,1.2000000000000002
18.771,0.0,0.0,-0.2,1.2000000000000002
18.797,0.0,0.0,-0.30000000000000004,1.2000000000000002
18.822,0.0,0.0,-0.30000000000000004,1.3
18.848,0.0,0.0,-0.4,1.3
18.873,0.0,0.0,-0.4,1.3
18.899,0.0,0.0,-0.4,1.3
18.924,0.0,0.0,-0.5,1.3
18.95,0.0,0.0,-0.5,1.3
18.975,0.0,0.0,-0.5,1.3
19.001,0.0,0.0,-0.6000000000000001,1.3
19.026,0.0,0.0,-0.6000000000000001,1.4000000000000001
19.052,0.0,0.0,-0.6000000000000001,1.4000000000000001
19.077,0.0,0.0,-0.6000000000000001,1.4000000000000001
19.103,0.0,0.0,-0.7000000000000001,1.4000000000000001
19.129,0.0,0.0,-0.7000000000000001,1.4000000000000001
19.154,0.0,0.0,-0.7000000000000001,1.4000000000000001
19.18,0.0,0.0,-0.7000000000000001,1.4000000000000001
19.206,0.0,0.0,-0.7000000000000001,1.4000000000000001
19.231,0.0,0.0,-0.7000000000000001,1.4000000000000001
19.257,0.0,0.0,-0.7000000000000001,1.4000000000000001
19.282,0.0,0.0,-0.7000000000000001,1.4000000000000001
19.308,0.0,0.0,-0.7000000000000001,1.4000000000000001
19.334,0.0,0.0,-0.7000000000000001,1.4000000000000001
19.359,0.0,0.0,-0.7000000000000001,1.4000000000000001
19.385,0.0,0.0,-0.7000000000000001,1.4000000000000001
19.411,0.0,0.0,-0.7000000000000001,1.4000000000000001
19.437,0.0,0.0,-0.7000000000000001,1.4000000000000001
19.462,0.0,0.0,-0.7000000000000001,1.4000000000000001
19.487000000000002,0.0,0.0,-0.7000000000000001,1.4000000000000001
19.513,0.0,0.0,-0.7000000000000001,1.4000000000000001
19.539,0.0,0.0,-0.7000000000000001,1.4000000000000001
19.564,0.0,0.0,-0.7000000000000001,1.4000000000000001
19.589,0.0,0.0,-0.7000000000000001,1.4000000000000001
19.615000000000002,0.0,0.0,-0.7000000000000001,1.4000000000000001
19.64,0.0,0.0,-0.7000000000000001,1.4000000000000001
19.665,0.0,0.0,-0.7000000000000001,1.4000000000000001
19.691,0.0,0.0,-0.7000000000000001,1.4000000000000001
19.716,0.0,0.0,-0.7000000000000001,1.4000000000000001
19.742,0.0,0.0,-0.7000000000000001,1.4000000000000001
19.768,0.0,0.0,-0.7000000000000001,1.4000000000000001
19.794,0.0,0.0,-0.7000000000000001,1.4000000000000001
19.82,0.0,0.0,-0.7000000000000001,1.4000000000000001
19.845,0.0,0.0,-0.7000000000000001,1.4000000000000001
19.871,0.0,0.0,-0.7000000000000001,1.4000000000000001
19.897000000000002,0.0,0.0,-0.7000000000000001,1.4000000000000001
19.923000000000002,0.0,0.0,-0.7000000000000001,1.4000000000000001
19.948,0.0,0.0,-0.7000000000000001,1.4000000000000001
19.973,0.0,0.0,-0.7000000000000001,1.4000000000000001
19.999,0.0,0.0,-0.7000000000000001,1.4000000000000001
20.025000000000002,0.0,0.0,-0.7000000000000001,1.4000000000000001
20.05,0.0,0.0,-0.7000000000000001,1.4000000000000001
20.076,0.0,0.0,-0.7000000000000001,1.4000000000000001
20.101,0.0,0.0,-0.7000000000000001,1.4000000000000001
20.127,0.0,0.0,-0.7000000000000001,1.4000000000000001
20.153,0.0,0.0,-0.7000000000000001,1.4000000000000001
20.178,0.0,0.0,-0.7000000000000001,1.4000000000000001
20.203,0.0,0.0,-0.7000000000000001,1.4000000000000001
20.229,0.0,0.0,-0.7000000000000001,1.4000000000000001
20.254,0.0,0.0,-0.7000000000000001,1.4000000000000001
20.28,0.0,0.0,-0.7000000000000001,1.4000000000000001
20.306,0.0,0.0,-0.7000000000000001,1.4000000000000001
20.331,0.0,0.0,-0.7000000000000001,1.4000000000000001
20.357,0.0,0.0,-0.7000000000000001,1.4000000000000001
20.382,0.0,0.0,-0.7000000000000001,1.4000000000000001
20.408,0.0,0.0,-0.7000000000000001,1.4000000000000001
20.433,0.3,21917.171047199787,-0.7000000000000001,1.4000000000000001
20.458000000000002,0.2,14611.44736479986,-0.7000000000000001,1.4000000000000001
20.483,0.1,7305.72368239993,-0.7000000000000001,1.4000000000000001
20.508,0.0,0.0,-0.7000000000000001,1.4000000000000001
20.534,0.0,0.0,-0.7000000000000001,1.4000000000000001
20.559,0.0,0.0,-0.7000000000000001,1.4000000000000001
20.584,0.0,0.0,-0.7000000000000001,1.4000000000000001
20.609,0.0,0.0,-0.7000000000000001,1.4000000000000001
20.634,0.0,0.0,-0.7000000000000001,1.4000000000000001
20.66,0.0,0.0,-0.7000000000000001,1.4000000000000001
20.685,0.0,0.0,-0.7000000000000001,1.4000000000000001
20.711000000000002,0.0,0.0,-0.7000000000000001,1.4000000000000001
20.736,0.0,0.0,-0.7000000000000001,1.4000000000000001
20.761,0.0,0.0,-0.7000000000000001,1.4000000000000001
20.786,0.0,0.0,-0.7000000000000001,1.4000000000000001
20.812,0.0,0.0,-0.7000000000000001,1.4000000000000001
20.838,0.0,0.0,-0.7000000000000001,1.4000000000000001
20.864,0.0,0.0,-0.7000000000000001,1.4000000000000001
20.89,0.0,0.0,-0.7000000000000001,1.4000000000000001
20.916,0.0,0.0,-0.7000000000000001,1.4000000000000001
20.941,0.0,0.0,-0.7000000000000001,1.4000000000000001
20.967,0.0,0.0,-0.7000000000000001,1.4000000000000001
20.992,0.0,0.0,-0.7000000000000001,1.4000000000000001
21.018,0.0,0.0,-0.7000000000000001,1.4000000000000001
21.043,0.1,7305.72368239993,-0.7000000000000001,1.4000000000000001
21.069,0.2,14611.44736479986,-0.7000000000000001,1.4000000000000001
21.094,0.1,7305.72368239993,-0.7000000000000001,1.4000000000000001
21.119,0.1,7305.72368239993,-0.7000000000000001,1.4000000000000001
21.145,0.1,7305.72368239993,-0.7000000000000001,1.4000000000000001
21.17,0.0,0.0,-0.7000000000000001,1.4000000000000001
21.195,0.0,0.0,-0.7000000000000001,1.4000000000000001
21.221,0.0,0.0,-0.7000000000000001,1.4000000000000001
21.247,0.0,0.0,-0.7000000000000001,1.4000000000000001
21.272000000000002,0.0,0.0,-0.7000000000000001,1.4000000000000001
21.298000000000002,0.0,0.0,-0.7000000000000001,1.4000000000000001
21.323,0.0,0.0,-0.7000000000000001,1.4000000000000001
21.349,0.0,0.0,-0.7000000000000001,1.4000000000000001
21.374,0.0,0.0,-0.7000000000000001,1.4000000000000001
21.399,0.0,0.0,-0.7000000000000001,1.4000000000000001
21.424,0.0,0.0,-0.7000000000000001,1.4000000000000001
21.45,0.0,0.0,-0.7000000000000001,1.4000000000000001
21.475,0.0,0.0,-0.7000000000000001,1.4000000000000001
21.501,0.0,0.0,-0.7000000000000001,1.4000000000000001
21.527,0.0,0.0,-0.7000000000000001,1.4000000000000001
21.552,0.0,0.0,-0.7000000000000001,1.4000000000000001
21.578,0.0,0.0,-0.7000000000000001,1.4000000000000001
21.603,0.0,0.0,-0.7000000000000001,1.4000000000000001
21.629,0.0,0.0,-0.7000000000000001,1.4000000000000001
21.654,0.0,0.0,-0.7000000000000001,1.4000000000000001
21.68,0.0,0.0,-0.7000000000000001,1.4000000000000001
21.706,0.0,0.0,-0.7000000000000001,1.4000000000000001
21.731,0.0,0.0,-0.7000000000000001,1.4000000000000001
21.757,0.0,0.0,-0.7000000000000001,1.4000000000000001
21.783,0.0,0.0,-0.7000000000000001,1.4000000000000001
21.808,0.0,0.0,-0.7000000000000001,1.4000000000000001
21.833000000000002,0.0,0.0,-0.7000000000000001,1.4000000000000001
21.858,0.0,0.0,-0.7000000000000001,1.4000000000000001
21.884,0.0,0.0,-0.7000000000000001,1.4000000000000001
21.909,0.0,0.0,-0.7000000000000001,1.4000000000000001
21.935,0.0,0.0,-0.7000000000000001,1.4000000000000001
21.96,0.0,0.0,-0.7000000000000001,1.4000000000000001
21.985,0.0,0.0,-0.7000000000000001,1.4000000000000001
22.011,0.0,0.0,-0.7000000000000001,1.4000000000000001
22.036,0.0,0.0,-0.7000000000000001,1.4000000000000001
22.062,0.0,0.0,-0.7000000000000001,1.4000000000000001
22.088,0.0,0.0,-0.7000000000000001,1.4000000000000001
22.113,0.0,0.0,-0.7000000000000001,1.4000000000000001
22.138,0.0,0.0,-0.7000000000000001,1.4000000000000001
22.164,0.0,0.0,-0.7000000000000001,1.4000000000000001
22.189,0.0,0.0,-0.7000000000000001,1.4000000000000001
22.215,0.0,0.0,-0.7000000000000001,1.4000000000000001
22.240000000000002,0.0,0.0,-0.7000000000000001,1.4000000000000001
22.266000000000002,0.0,0.0,-0.7000000000000001,1.4000000000000001
22.291,0.0,0.0,-0.7000000000000001,1.4000000000000001
22.317,0.0,0.0,-0.7000000000000001,1.4000000000000001
22.342,0.0,0.0,-0.7000000000000001,1.4000000000000001
22.367,0.0,0.0,-0.7000000000000001,1.4000000000000001
22.393,0.0,0.0,-0.7000000000000001,1.4000000000000001
22.419,0.0,0.0,-0.7000000000000001,1.4000000000000001
22.445,0.0,0.0,-0.7000000000000001,1.4000000000000001
22.471,0.0,0.0,-0.7000000000000001,1.4000000000000001
22.496000000000002,0.0,0.0,-0.7000000000000001,1.4000000000000001
22.521,0.0,0.0,-0.7000000000000001,1.4000000000000001
22.547,0.0,0.0,-0.7000000000000001,1.4000000000000001
22.572,0.0,0.0,-0.7000000000000001,1.4000000000000001
22.597,0.0,0.0,-0.7000000000000001,1.4000000000000001
22.623,0.0,0.0,-0.7000000000000001,1.4000000000000001
22.649,0.0,0.0,-0.7000000000000001,1.4000000000000001
22.674,0.0,0.0,-0.7000000000000001,1.4000000000000001
22.7,0.0,0.0,-0.7000000000000001,1.4000000000000001
22.726,0.0,0.0,-0.7000000000000001,1.4000000000000001
22.752,0.0,0.0,-0.7000000000000001,1.4000000000000001
22.777,0.0,0.0,-0.7000000000000001,1.4000000000000001
22.803,0.0,0.0,-0.7000000000000001,1.4000000000000001
22.828,0.0,0.0,-0.7000000000000001,1.4000000000000001
22.854,0.0,0.0,-0.7000000000000001,1.4000000000000001
22.879,0.0,0.0,-0.7000000000000001,1.4000000000000001
22.904,0.0,0.0,-0.7000000000000001,1.4000000000000001
22.93,0.0,0.0,-0.7000000000000001,1.4000000000000001
22.956,0.0,0.0,-0.7000000000000001,1.4000000000000001
22.981,0.0,0.0,-0.7000000000000001,1.4000000000000001
23.006,0.0,0.0,-0.7000000000000001,1.4000000000000001
23.032,0.0,0.0,-0.7000000000000001,1.4000000000000001
23.057000000000002,0.0,0.0,-0.7000000000000001,1.4000000000000001
23.082,0.0,0.0,-0.7000000000000001,1.4000000000000001
23.108,0.0,0.0,-0.7000000000000001,1.4000000000000001
23.133,0.0,0.0,-0.7000000000000001,1.4000000000000001
23.158,0.0,0.0,-0.7000000000000001,1.4000000000000001
23.184,0.0,0.0,-0.7000000000000001,1.4000000000000001
23.209,0.0,0.0,-0.7000000000000001,1.4000000000000001
23.234,0.0,0.0,-0.7000000000000001,1.4000000000000001
23.26,0.0,0.0,-0.7000000000000001,1.4000000000000001
23.44,0.0,0.0,-0.7000000000000001,1.4000000000000001

23.312,0.0,0.0,-0.7000000000000001,1.4000000000000001
23.337,0.0,0.0,-0.7000000000000001,1.4000000000000001
23.363,0.0,0.0,-0.7000000000000001,1.4000000000000001
23.389,0.0,0.0,-0.7000000000000001,1.4000000000000001
23.414,0.0,0.0,-0.7000000000000001,1.4000000000000001
23.465,0.0,0.0,-0.7000000000000001,1.4000000000000001
23.490000000000002,0.0,0.0,-0.7000000000000001,1.4000000000000001
23.515,0.0,0.0,-0.7000000000000001,1.4000000000000001
23.541,0.0,0.0,-0.7000000000000001,1.4000000000000001
23.567,0.0,0.0,-0.7000000000000001,1.4000000000000001
23.593,0.0,0.0,-0.7000000000000001,1.4000000000000001
23.618000000000002,0.0,0.0,-0.7000000000000001,1.4000000000000001
23.644000000000002,0.0,0.0,-0.7000000000000001,1.4000000000000001
23.669,0.0,0.0,-0.7000000000000001,1.4000000000000001
23.695,0.0,0.0,-0.7000000000000001,1.4000000000000001
23.721,0.0,0.0,-0.7000000000000001,1.4000000000000001
23.746000000000002,0.0,0.0,-0.7000000000000001,1.4000000000000001
23.772000000000002,0.0,0.0,-0.7000000000000001,1.4000000000000001
23.798000000000002,0.0,0.0,-0.7000000000000001,1.4000000000000001
23.823,0.0,0.0,-0.7000000000000001,1.4000000000000001
23.849,0.0,0.0,-0.7000000000000001,1.4000000000000001
23.875,0.0,0.0,-0.7000000000000001,1.4000000000000001
23.900000000000002,0.0,0.0,-0.7000000000000001,1.4000000000000001
23.925,0.0,0.0,-0.7000000000000001,1.4000000000000001
23.95,0.0,0.0,-0.7000000000000001,1.4000000000000001
23.976,0.0,0.0,-0.7000000000000001,1.4000000000000001
24.002,0.0,0.0,-0.7000000000000001,1.4000000000000001
24.028000000000002,0.0,0.0,-0.7000000000000001,1.4000000000000001
24.053,0.0,0.0,-0.7000000000000001,1.4000000000000001
24.078,0.0,0.0,-0.7000000000000001,1.4000000000000001
24.104,0.0,0.0,-0.7000000000000001,1.4000000000000001
24.129,0.0,0.0,-0.7000000000000001,1.4000000000000001
24.155,0.0,0.0,-0.7000000000000001,1.4000000000000001
24.18,0.0,0.0,-0.7000000000000001,1.4000000000000001
24.206,0.0,0.0,-0.7000000000000001,1.4000000000000001
24.231,0.0,0.0,-0.7000000000000001,1.4000000000000001
24.256,0.0,0.0,-0.7000000000000001,1.4000000000000001
24.46,0.0,0.0,-0.7000000000000001,1.4000000000000001

24.307000000000002,0.0,0.0,-0.7000000000000001,1.4000000000000001
24.332,0.0,0.0,-0.7000000000000001,1.4000000000000001
24.358,0.0,0.0,-0.7000000000000001,1.4000000000000001
24.384,0.0,0.0,-0.7000000000000001,1.4000000000000001
24.409,0.0,0.0,-0.7000000000000001,1.4000000000000001
24.434,0.0,0.0,-0.7000000000000001,1.4000000000000001
24.485,0.0,0.0,-0.7000000000000001,1.4000000000000001
24.511,0.0,0.0,-0.7000000000000001,1.4000000000000001
24.536,0.0,0.0,-0.7000000000000001,1.4000000000000001
24.562,0.0,0.0,-0.7000000000000001,1.4000000000000001
24.588,0.0,0.0,-0.7000000000000001,1.4000000000000001
24.613,0.0,0.0,-0.7000000000000001,1.4000000000000001
24.639,0.0,0.0,-0.7000000000000001,1.4000000000000001
24.665,0.0,0.0,-0.7000000000000001,1.4000000000000001
24.691,0.0,0.0,-0.7000000000000001,1.4000000000000001
24.716,0.0,0.0,-0.7000000000000001,1.4000000000000001
24.743000000000002,0.0,0.0,-0.7000000000000001,1.4000000000000001
24.768,0.0,0.0,-0.7000000000000001,1.4000000000000001
24.794,0.0,0.0,-0.7000000000000001,1.4000000000000001
24.82,0.0,0.0,-0.7000000000000001,1.4000000000000001
24.846,0.0,0.0,-0.7000000000000001,1.4000000000000001
24.872,0.0,0.0,-0.7000000000000001,1.4000000000000001
24.898,0.0,0.0,-0.7000000000000001,1.4000000000000001
24.923000000000002,0.0,0.0,-0.7000000000000001,1.4000000000000001
24.949,0.0,0.0,-0.7000000000000001,1.4000000000000001
24.974,0.0,0.0,-0.7000000000000001,1.4000000000000001
25.0,0.0,0.0,-0.7000000000000001,1.4000000000000001
25.025000000000002,0.0,0.0,-0.7000000000000001,1.4000000000000001
25.05,0.0,0.0,-0.7000000000000001,1.4000000000000001
25.075,0.0,0.0,-0.7000000000000001,1.4000000000000001
25.101,0.0,0.0,-0.7000000000000001,1.4000000000000001
25.126,0.0,0.0,-0.7000000000000001,1.4000000000000001
25.152,0.0,0.0,-0.7000000000000001,1.4000000000000001
25.177,0.0,0.0,-0.7000000000000001,1.4000000000000001
25.203,0.0,0.0,-0.7000000000000001,1.4000000000000001
25.228,0.0,0.0,-0.7000000000000001,1.4000000000000001
25.254,0.0,0.0,-0.7000000000000001,1.4000000000000001
25.279,0.0,0.0,-0.7000000000000001,1.4000000000000001
25.305,0.0,0.0,-0.7000000000000001,1.4000000000000001
25.331,0.0,0.0,-0.7000000000000001,1.4000000000000001
25.357,0.0,0.0,-0.7000000000000001,1.4000000000000001
25.382,0.0,0.0,-0.7000000000000001,1.4000000000000001
25.408,0.0,0.0,-0.7000000000000001,1.4000000000000001
25.433,0.0,0.0,-0.7000000000000001,1.4000000000000001
25.458000000000002,0.0,0.0,-0.7000000000000001,1.4000000000000001
25.484,0.0,0.0,-0.7000000000000001,1.4000000000000001
25.51,0.0,0.0,-0.7000000000000001,1.4000000000000001
25.535,0.0,0.0,-0.7000000000000001,1.4000000000000001
25.561,0.0,0.0,-0.7000000000000001,1.4000000000000001
25.587,0.0,0.0,-0.7000000000000001,1.4000000000000001
25.612000000000002,0.0,0.0,-0.7000000000000001,1.4000000000000001
25.638,0.0,0.0,-0.7000000000000001,1.4000000000000001
25.663,0.0,0.0,-0.7000000000000001,1.4000000000000001
25.689,0.0,0.0,-0.7000000000000001,1.4000000000000001
25.714000000000002,0.0,0.0,-0.7000000000000001,1.4000000000000001
25.739,0.0,0.0,-0.7000000000000001,1.4000000000000001
25.765,0.0,0.0,-0.7000000000000001,1.4000000000000001
25.79,0.0,0.0,-0.7000000000000001,1.4000000000000001
25.816,0.0,0.0,-0.7000000000000001,1.4000000000000001
25.841,0.0,0.0,-0.7000000000000001,1.4000000000000001
25.867,0.0,0.0,-0.7000000000000001,1.4000000000000001
25.892,0.0,0.0,-0.7000000000000001,1.4000000000000001
25.917,0.0,0.0,-0.7000000000000001,1.4000000000000001
25.942,0.0,0.0,-0.7000000000000001,1.4000000000000001
25.968,0.0,0.0,-0.7000000000000001,1.4000000000000001
25.993000000000002,0.0,0.0,-0.7000000000000001,1.4000000000000001
26.019000000000002,0.0,0.0,-0.7000000000000001,1.4000000000000001
26.044,0.0,0.0,-0.7000000000000001,1.4000000000000001
26.07,0.0,0.0,-0.7000000000000001,1.4000000000000001
26.096,0.0,0.0,-0.7000000000000001,1.4000000000000001
26.121000000000002,0.0,0.0,-0.7000000000000001,1.4000000000000001
26.147000000000002,0.0,0.0,-0.7000000000000001,1.4000000000000001
26.172,0.0,0.0,-0.7000000000000001,1.4000000000000001
26.198,0.0,0.0,-0.7000000000000001,1.4000000000000001
26.224,0.0,0.0,-0.7000000000000001,1.4000000000000001
26.25,0.0,0.0,-0.7000000000000001,1.4000000000000001
26.275000000000002,0.0,0.0,-0.7000000000000001,1.4000000000000001
26.3,0.0,0.0,-0.7000000000000001,1.4000000000000001
26.326,0.0,0.0,-0.7000000000000001,1.4000000000000001
26.351,0.0,0.0,-0.7000000000000001,1.4000000000000001
26.376,0.0,0.0,-0.7000000000000001,1.4000000000000001
26.402,0.0,0.0,-0.7000000000000001,1.4000000000000001
26.427,0.0,0.0,-0.7000000000000001,1.4000000000000001
26.453,0.0,0.0,-0.7000000000000001,1.4000000000000001
26.478,0.0,0.0,-0.7000000000000001,1.4000000000000001
26.503,0.0,0.0,-0.7000000000000001,1.4000000000000001
26.529,0.0,0.0,-0.7000000000000001,1.4000000000000001
26.554000000000002,0.0,0.0,-0.7000000000000001,1.4000000000000001
26.580000000000002,0.0,0.0,-0.7000000000000001,1.4000000000000001
26.605,0.0,0.0,-0.7000000000000001,1.4000000000000001
26.63,0.0,0.0,-0.7000000000000001,1.4000000000000001
26.656,0.0,0.0,-0.7000000000000001,1.4000000000000001
26.682000000000002,0.0,0.0,-0.7000000000000001,1.4000000000000001
26.707,0.0,0.0,-0.7000000000000001,1.4000000000000001
26.732,0.0,0.0,-0.7000000000000001,1.4000000000000001
26.758,0.0,0.0,-0.7000000000000001,1.4000000000000001
26.783,0.0,0.0,-0.7000000000000001,1.4000000000000001
26.809,0.0,0.0,-0.7000000000000001,1.4000000000000001
26.834,0.0,0.0,-0.7000000000000001,1.4000000000000001
26.86,0.0,0.0,-0.7000000000000001,1.4000000000000001
26.885,0.0,0.0,-0.7000000000000001,1.4000000000000001
26.91,0.0,0.0,-0.7000000000000001,1.4000000000000001
26.936,0.0,0.0,-0.7000000000000001,1.4000000000000001
26.961000000000002,0.0,0.0,-0.7000000000000001,1.4000000000000001
26.987000000000002,0.0,0.0,-0.7000000000000001,1.4000000000000001
27.012,0.0,0.0,-0.7000000000000001,1.4000000000000001
27.037,0.0,0.0,-0.7000000000000001,1.4000000000000001
27.063,0.0,0.0,-0.7000000000000001,1.4000000000000001
27.089000000000002,0.0,0.0,-0.7000000000000001,1.4000000000000001
27.114,0.0,0.0,-0.7000000000000001,1.4000000000000001
27.14,0.0,0.0,-0.7000000000000001,1.4000000000000001
27.166,0.0,0.0,-0.7000000000000001,1.4000000000000001
27.191,0.0,0.0,-0.7000000000000001,1.4000000000000001
27.217000000000002,0.0,0.0,-0.7000000000000001,1.4000000000000001
27.242,0.0,0.0,-0.7000000000000001,1.4000000000000001
27.267,0.0,0.0,-0.7000000000000001,1.4000000000000001
27.293,0.0,0.0,-0.7000000000000001,1.4000000000000001
27.319,0.0,0.0,-0.7000000000000001,1.4000000000000001
27.344,0.0,0.0,-0.7000000000000001,1.4000000000000001
27.37,0.0,0.0,-0.7000000000000001,1.4000000000000001
27.396,0.0,0.0,-0.7000000000000001,1.4000000000000001
27.421,0.0,0.0,-0.7000000000000001,1.4000000000000001
27.446,0.0,0.0,-0.7000000000000001,1.4000000000000001
27.472,0.0,0.0,-0.7000000000000001,1.4000000000000001
27.498,0.0,0.0,-0.7000000000000001,1.4000000000000001
27.523,0.0,0.0,-0.7000000000000001,1.4000000000000001
27.549,0.0,0.0,-0.7000000000000001,1.4000000000000001
27.574,0.0,0.0,-0.7000000000000001,1.4000000000000001
27.6,0.0,0.0,-0.7000000000000001,1.4000000000000001
27.626,0.0,0.0,-0.7000000000000001,1.4000000000000001
27.652,0.0,0.0,-0.7000000000000001,1.4000000000000001
27.677,0.0,0.0,-0.7000000000000001,1.4000000000000001
27.702,0.0,0.0,-0.7000000000000001,1.4000000000000001
27.728,0.0,0.0,-0.7000000000000001,1.4000000000000001
27.753,0.0,0.0,-0.7000000000000001,1.4000000000000001
27.779,0.0,0.0,-0.7000000000000001,1.4000000000000001
27.804000000000002,0.0,0.0,-0.7000000000000001,1.4000000000000001
27.830000000000002,0.0,0.0,-0.7000000000000001,1.4000000000000001
27.855,0.0,0.0,-0.7000000000000001,1.4000000000000001
27.881,0.0,0.0,-0.7000000000000001,1.4000000000000001
27.907,0.0,0.0,-0.7000000000000001,1.4000000000000001
27.932000000000002,0.0,0.0,-0.7000000000000001,1.4000000000000001
27.957,0.0,0.0,-0.7000000000000001,1.4000000000000001
27.983,0.0,0.0,-0.7000000000000001,1.4000000000000001
28.008,0.0,0.0,-0.7000000000000001,1.4000000000000001
28.034,0.0,0.0,-0.7000000000000001,1.4000000000000001
28.059,0.0,0.0,-0.7000000000000001,1.4000000000000001
28.085,0.0,0.0,-0.7000000000000001,1.4000000000000001
28.11,0.0,0.0,-0.7000000000000001,1.4000000000000001
28.135,0.0,0.0,-0.7000000000000001,1.4000000000000001
28.161,0.0,0.0,-0.7000000000000001,1.4000000000000001
28.186,0.0,0.0,-0.7000000000000001,1.4000000000000001
28.212,0.0,0.0,-0.7000000000000001,1.4000000000000001
28.238,0.0,0.0,-0.7000000000000001,1.4000000000000001
28.263,0.0,0.0,-0.7000000000000001,1.4000000000000001
28.289,0.0,0.0,-0.7000000000000001,1.4000000000000001
28.314,0.0,0.0,-0.7000000000000001,1.4000000000000001
28.34,0.0,0.0,-0.7000000000000001,1.4000000000000001
28.366,0.0,0.0,-0.7000000000000001,1.4000000000000001
28.392,0.0,0.0,-0.7000000000000001,1.4000000000000001
28.418,0.0,0.0,-0.7000000000000001,1.4000000000000001
28.443,0.0,0.0,-0.7000000000000001,1.4000000000000001
28.468,0.0,0.0,-0.7000000000000001,1.4000000000000001
28.494,0.0,0.0,-0.7000000000000001,1.4000000000000001
28.52,0.0,0.0,-0.7000000000000001,1.4000000000000001
28.545,0.0,0.0,-0.7000000000000001,1.4000000000000001
28.57,0.0,0.0,-0.7000000000000001,1.4000000000000001
28.596,0.0,0.0,-0.7000000000000001,1.4000000000000001
28.622,0.0,0.0,-0.7000000000000001,1.4000000000000001
28.647000000000002,0.0,0.0,-0.7000000000000001,1.4000000000000001
28.673000000000002,0.0,0.0,-0.7000000000000001,1.4000000000000001
28.698,0.0,0.0,-0.7000000000000001,1.4000000000000001
28.724,0.0,0.0,-0.7000000000000001,1.4000000000000001
28.749000000000002,0.0,0.0,-0.7000000000000001,1.4000000000000001
28.775000000000002,0.0,0.0,-0.7000000000000001,1.4000000000000001
28.8,0.0,0.0,-0.7000000000000001,1.4000000000000001
28.826,0.0,0.0,-0.7000000000000001,1.4000000000000001
28.852,0.0,0.0,-0.7000000000000001,1.4000000000000001
28.878,0.0,0.0,-0.7000000000000001,1.4000000000000001
28.903000000000002,0.0,0.0,-0.7000000000000001,1.4000000000000001
28.929000000000002,0.0,0.0,-0.7000000000000001,1.4000000000000001
28.954,0.0,0.0,-0.7000000000000001,1.4000000000000001
28.979,0.0,0.0,-0.7000000000000001,1.4000000000000001
29.005,0.0,0.0,-0.7000000000000001,1.4000000000000001
29.031000000000002,0.0,0.0,-0.7000000000000001,1.4000000000000001
29.056,0.0,0.0,-0.7000000000000001,1.4000000000000001
29.082,0.0,0.0,-0.7000000000000001,1.4000000000000001
29.107,0.0,0.0,-0.7000000000000001,1.4000000000000001
29.133,0.0,0.0,-0.7000000000000001,1.4000000000000001
29.339000000000002,0.0,0.0,-0.7000000000000001,1.4000000000000001
.0,-0.7000000000000001,1.4000000000000001
29.21,0.0,0.0,-0.7000000000000001,1.4000000000000001
29.236,0.0,0.0,-0.7000000000000001,1.4000000000000001
29.262,0.0,0.0,-0.7000000000000001,1.4000000000000001
29.287,0.0,0.0,-0.7000000000000001,1.4000000000000001
29.313,0.0,0.0,-0.7000000000000001,1.4000000000000001
29.364,0.0,0.0,-0.7000000000000001,1.4000000000000001
29.39,0.0,0.0,-0.7000000000000001,1.4000000000000001
29.415,0.0,0.0,-0.7000000000000001,1.4000000000000001
29.441,0.0,0.0,-0.7000000000000001,1.4000000000000001
29.466,0.0,0.0,-0.7000000000000001,1.4000000000000001
29.492,0.0,0.0,-0.7000000000000001,1.4000000000000001
29.517,0.0,0.0,-0.7000000000000001,1.4000000000000001
29.543,0.0,0.0,-0.7000000000000001,1.4000000000000001
29.568,0.0,0.0,-0.7000000000000001,1.4000000000000001
29.593,0.0,0.0,-0.7000000000000001,1.4000000000000001
29.619,0.0,0.0,-0.7000000000000001,1.4000000000000001
29.644000000000002,0.0,0.0,-0.7000000000000001,1.4000000000000001
29.67,0.0,0.0,-0.7000000000000001,1.4000000000000001
29.695,0.0,0.0,-0.7000000000000001,1.4000000000000001
29.721,0.0,0.0,-0.7000000000000001,1.4000000000000001
29.747,0.0,0.0,-0.7000000000000001,1.4000000000000001
29.772000000000002,0.0,0.0,-0.7000000000000001,1.4000000000000001
29.798000000000002,0.0,0.0,-0.7000000000000001,1.4000000000000001
29.824,0.0,0.0,-0.7000000000000001,1.4000000000000001
29.85,0.0,0.0,-0.7000000000000001,1.4000000000000001
29.875,0.0,0.0,-0.7000000000000001,1.4000000000000001
29.900000000000002,0.0,0.0,-0.7000000000000001,1.4000000000000001
29.926000000000002,0.0,0.0,-0.7000000000000001,1.4000000000000001
29.952,0.0,0.0,-0.7000000000000001,1.4000000000000001
29.977,0.0,0.0,-0.7000000000000001,1.4000000000000001
30.003,0.0,0.0,-0.7000000000000001,1.4000000000000001